Workbook

Sheet Start Here
A1: BrainBench — Statistical Analysis Report
A2: Generated 2026-04-17 14:02
A4: About this workbook
A5: We tested three small local AI models (Gemma3:4b, Phi3:3.8b, Qwen3:4b) on three math question sets (Calculus I, Advanced Probability & Statistics, Grade 8 Math). For every question we recorded whether the answer was right and how long, how much energy, and how many output tokens the model used. This workbook answers: which model is most accurate, which is most energy-efficient, where the wrong answers come from, and whether the differences between models are real (statistically significant) or just noise.
A7: How to read this workbook
A8: • Every data sheet opens with a 3-line header block: title, one-sentence description, and 'How to read'. • Numbers are formatted for humans — accuracies as percentages, tiny p-values in scientific notation. • Cells are color-coded. Accuracy uses a red → yellow → green scale. Significant Holm-adjusted p-values (< 0.05) are shaded green; non-significant are gray. Cohen's κ uses the same palette as the agreement heatmap figure. • Unfamiliar term? See the Glossary sheet at the end — it is keyboard-searchable.
A10: Suggested reading order
A11: # | B11: Sheet | C11: What it shows
A12: ★ | B12: Dashboard | C12: Visual overview — the headline charts in one place. Open this first for a quick read, then dive into the numbered sheets below for details.
A13: 1 | B13: Executive Summary | C13: One line per dataset: the winning model, the most energy-efficient model, and how many pairs of models were genuinely different.
A14: 2 | B14: Accuracy | C14: How often each model got the right answer on each dataset, with a 95% confidence range.
A15: 3 | B15: Per Category Accuracy | C15: Accuracy split by question category within each dataset — where each model is strong or weak.
A16: 4 | B16: Efficiency | C16: Bang-for-the-buck: correct answers per unit of energy, per 1,000 output tokens, and per minute of wall time.
A17: 5 | B17: Failure Modes | C17: When a model is wrong, is it because the answer couldn't be parsed from the output, or because the parsed answer was the wrong number?
A18: 6 | B18: Metric Summary | C18: Typical per-question cost for each model: how long it takes, how many tokens it writes, how much energy it uses.
A19: 7 | B19: McNemar | C19: For each pair of models on each dataset: are the accuracy scores actually different, or is the gap within the noise?
A20: 8 | B20: Metric Comparison | C20: For each pair of models, does one use significantly more/less time, tokens, or energy per question?
A21: 9 | B21: Run Variance | C21: How much the accuracy wobbles if you re-run the same model on the same dataset.
A22: 10 | B22: Glossary | C22: Plain-English definitions for every statistical term used in this workbook.

Sheet Dashboard
A1: BrainBench — Visual Dashboard
A2: Gemma3:4b vs Phi3:3.8b vs Qwen3:4b across three math datasets.
A3: ● Gemma3:4b (blue) ● Phi3:3.8b (orange) ● Qwen3:4b (green)
O5: Accuracy
O6: Dataset | P6: Gemma3:4b | Q6: Phi3:3.8b | R6: Qwen3:4b
O7: Adv Probability & Statistics | P7: =Accuracy!E6 | Q7: =Accuracy!E7 | R7: =Accuracy!E8
O8: Calculus I | P8: =Accuracy!E9 | Q8: =Accuracy!E10 | R8: =Accuracy!E11
O9: Grade 8 Math | P9: =Accuracy!E12 | Q9: =Accuracy!E13 | R9: =Accuracy!E14
O11: Correct per Wh
O12: Dataset | P12: Gemma3:4b | Q12: Phi3:3.8b | R12: Qwen3:4b
O13: Adv Probability & Statistics | P13: =Efficiency!I6 | Q13: =Efficiency!I7 | R13: =Efficiency!I8
O14: Calculus I | P14: =Efficiency!I9 | Q14: =Efficiency!I10 | R14: =Efficiency!I11
O15: Grade 8 Math | P15: =Efficiency!I12 | Q15: =Efficiency!I13 | R15: =Efficiency!I14
O17: Correct per 1k Tokens
O18: Dataset | P18: Gemma3:4b | Q18: Phi3:3.8b | R18: Qwen3:4b
O19: Adv Probability & Statistics | P19: =Efficiency!J6 | Q19: =Efficiency!J7 | R19: =Efficiency!J8
O20: Calculus I | P20: =Efficiency!J9 | Q20: =Efficiency!J10 | R20: =Efficiency!J11
O21: Grade 8 Math | P21: =Efficiency!J12 | Q21: =Efficiency!J13 | R21: =Efficiency!J14
O23: Energy per Question (Wh)
O24: Dataset | P24: Gemma3:4b | Q24: Phi3:3.8b | R24: Qwen3:4b
O25: Adv Probability & Statistics | P25: =Efficiency!L6 | Q25: =Efficiency!L7 | R25: =Efficiency!L8
O26: Calculus I | P26: =Efficiency!L9 | Q26: =Efficiency!L10 | R26: =Efficiency!L11
O27: Grade 8 Math | P27: =Efficiency!L12 | Q27: =Efficiency!L13 | R27: =Efficiency!L14
O29: Wrong Answer Rate
O30: Dataset | P30: Gemma3:4b | Q30: Phi3:3.8b | R30: Qwen3:4b
O31: Adv Probability & Statistics | P31: =Failure_Modes!J6 | Q31: =Failure_Modes!J7 | R31: =Failure_Modes!J8
O32: Calculus I | P32: =Failure_Modes!J9 | Q32: =Failure_Modes!J10 | R32: =Failure_Modes!J11
O33: Grade 8 Math | P33: =Failure_Modes!J12 | Q33: =Failure_Modes!J13 | R33: =Failure_Modes!J14
O35: Tokens per Question (avg)
O36: Dataset | P36: Gemma3:4b | Q36: Phi3:3.8b | R36: Qwen3:4b
O37: Adv Probability & Statistics | P37: =Efficiency!M6 | Q37: =Efficiency!M7 | R37: =Efficiency!M8
O38: Calculus I | P38: =Efficiency!M9 | Q38: =Efficiency!M10 | R38: =Efficiency!M11
O39: Grade 8 Math | P39: =Efficiency!M12 | Q39: =Efficiency!M13 | R39: =Efficiency!M14
O41: Total Time (s)
O42: Dataset | P42: Gemma3:4b | Q42: Phi3:3.8b | R42: Qwen3:4b
O43: Adv Probability & Statistics | P43: =Efficiency!H6 | Q43: =Efficiency!H7 | R43: =Efficiency!H8
O44: Calculus I | P44: =Efficiency!H9 | Q44: =Efficiency!H10 | R44: =Efficiency!H11
O45: Grade 8 Math | P45: =Efficiency!H12 | Q45: =Efficiency!H13 | R45: =Efficiency!H14
O47: Run Variance — Mean Accuracy
O48: Dataset | P48: Gemma3:4b | Q48: Phi3:3.8b | R48: Qwen3:4b
...

Sheet Executive_Summary
A1: Executive Summary
A2: One line per dataset: the winning model, the most energy-efficient model, and how many pairs of models were genuinely different.
A3: How to read: Start here. Read the 'Takeaway' column — it is a plain-English summary. Everything else in the workbook is the evidence behind these sentences.
A5: Dataset | B5: Best Model (Accuracy) | C5: Accuracy | D5: Best Model (Correct/Wh) | E5: Correct per Wh | F5: McNemar Significant Pairs (Holm) | G5: Takeaway
A6: Adv Probability & Statistics | B6: Qwen3:4b | C6: 0.975 | D6: Gemma3:4b | E6: 6.5251507 | F6: 3/3 | G6: Qwen3:4b is the most accurate (97.5%). Gemma3:4b is the most energy-efficient (6.53 correct/Wh). 3 of 3 model pairs differ significantly in accuracy.
A7: Calculus I | B7: Gemma3:4b | C7: 0.86363636 | D7: Gemma3:4b | E7: 4.4469165 | F7: 3/3 | G7: Gemma3:4b is the most accurate (86.4%). Gemma3:4b is the most energy-efficient (4.45 correct/Wh). 3 of 3 model pairs differ significantly in accuracy.
A8: Grade 8 Math | B8: Qwen3:4b | C8: 0.7826087 | D8: Gemma3:4b | E8: 4.837542 | F8: 3/3 | G8: Qwen3:4b is the most accurate (78.3%). Gemma3:4b is the most energy-efficient (4.84 correct/Wh). 3 of 3 model pairs differ significantly in accuracy.

Sheet Accuracy
A1: Accuracy
A2: How often each model got the right answer on each dataset, with a 95% confidence range.
A3: How to read: 'Accuracy' is the score (higher is better). 'Wilson 95% CI Lower/Upper' is the range the true score likely falls in — wider = less certain (usually because N is small). If two models' CIs don't overlap, their scores probably really are different.
A5: Model | B5: Dataset | C5: N | D5: Correct | E5: Accuracy | F5: Wilson 95% CI Lower | G5: Wilson 95% CI Upper
A6: Gemma3:4b | B6: Adv Probability & Statistics | C6: 884 | D6: 837 | E6: 0.94683258 | F6: 0.93001474 | G6: 0.95978376
A7: Phi3:3.8b | B7: Adv Probability & Statistics | C7: 1000 | D7: 92 | E7: 0.092 | F7: 0.0756139 | G7: 0.11150874
A8: Qwen3:4b | B8: Adv Probability & Statistics | C8: 1000 | D8: 975 | E8: 0.975 | F8: 0.96335471 | G8: 0.98300987
A9: Gemma3:4b | B9: Calculus I | C9: 374 | D9: 323 | E9: 0.86363636 | F9: 0.82513984 | G9: 0.89473881
A10: Phi3:3.8b | B10: Calculus I | C10: 900 | D10: 110 | E10: 0.12222222 | F10: 0.10241404 | G10: 0.14524163
A11: Qwen3:4b | B11: Calculus I | C11: 900 | D11: 718 | E11: 0.79777778 | F11: 0.77029632 | G11: 0.82272803
A12: Gemma3:4b | B12: Grade 8 Math | C12: 644 | D12: 435 | E12: 0.67546584 | F12: 0.63835703 | G12: 0.71049375
A13: Phi3:3.8b | B13: Grade 8 Math | C13: 644 | D13: 16 | E13: 0.02484472 | F13: 0.015349697 | G13: 0.039974732
A14: Qwen3:4b | B14: Grade 8 Math | C14: 644 | D14: 504 | E14: 0.7826087 | F14: 0.74912681 | G14: 0.81273906

Sheet Per_Category_Accuracy
A1: Per Category Accuracy
A2: Accuracy split by question category within each dataset — where each model is strong or weak.
A3: How to read: Look for categories where one model is much better or worse than the others. If 'N' is small, the accuracy is a noisy estimate (the CI will be wide).
A5: Model | B5: Dataset | C5: Category | D5: N | E5: Correct | F5: Accuracy | G5: Wilson 95% CI Lower | H5: Wilson 95% CI Upper
A6: Gemma3:4b | B6: Adv Probability & Statistics | C6: Advanced Probability & Statistics | D6: 884 | E6: 837 | F6: 0.94683258 | G6: 0.93001474 | H6: 0.95978376
A7: Phi3:3.8b | B7: Adv Probability & Statistics | C7: Advanced Probability & Statistics | D7: 1000 | E7: 92 | F7: 0.092 | G7: 0.0756139 | H7: 0.11150874
A8: Qwen3:4b | B8: Adv Probability & Statistics | C8: Advanced Probability & Statistics | D8: 1000 | E8: 975 | F8: 0.975 | G8: 0.96335471 | H8: 0.98300987
A9: Gemma3:4b | B9: Calculus I | C9: Calculus I | D9: 374 | E9: 323 | F9: 0.86363636 | G9: 0.82513984 | H9: 0.89473881
A10: Phi3:3.8b | B10: Calculus I | C10: Calculus I | D10: 900 | E10: 110 | F10: 0.12222222 | G10: 0.10241404 | H10: 0.14524163
A11: Qwen3:4b | B11: Calculus I | C11: Calculus I | D11: 900 | E11: 718 | F11: 0.79777778 | G11: 0.77029632 | H11: 0.82272803
A12: Gemma3:4b | B12: Grade 8 Math | C12: Expressions and Equations | D12: 186 | E12: 94 | F12: 0.50537634 | G12: 0.43414654 | H12: 0.57638857
A13: Phi3:3.8b | B13: Grade 8 Math | C13: Expressions and Equations | D13: 186 | E13: 1 | F13: 0.0053763441 | G13: 0.00094968803 | H13: 0.029820508
A14: Qwen3:4b | B14: Grade 8 Math | C14: Expressions and Equations | D14: 186 | E14: 110 | F14: 0.59139785 | G14: 0.5195973 | H14: 0.65949951
A15: Gemma3:4b | B15: Grade 8 Math | C15: Functions | D15: 88 | E15: 76 | F15: 0.86363636 | G15: 0.7766125 | H15: 0.92024055
A16: Phi3:3.8b | B16: Grade 8 Math | C16: Functions | D16: 88 | E16: 0 | F16: 0 | G16: 0 | H16: 0.041827067
A17: Qwen3:4b | B17: Grade 8 Math | C17: Functions | D17: 88 | E17: 86 | F17: 0.97727273 | G17: 0.92087455 | H17: 0.99374507
... A29: Qwen3:4b | B29: Grade 8 Math | C29: unknown | D29: 1 | E29: 1 | F29: 1 | G29: 0.20654931 | H29: 1

Sheet Efficiency
A1: Efficiency
A2: Bang-for-the-buck: correct answers per unit of energy, per 1,000 output tokens, and per minute of wall time.
A3: How to read: Bigger 'Correct per Wh / 1k Tokens / Minute' is better — the model squeezes more right answers out of each unit spent. Smaller 'Energy per Question' and 'Tokens per Question' is better (cheaper). A fast, cheap model that's also wrong isn't useful — always check Accuracy too.
A5: Model | B5: Dataset | C5: N | D5: Correct | E5: Accuracy | F5: Total Energy (Wh) | G5: Total Output Tokens | H5: Total Time (s) | I5: Correct per Wh | J5: Correct per 1k Tokens | K5: Correct per Minute | L5: Energy per Question (Wh) | M5: Tokens per Question
A6: Gemma3:4b | B6: Adv Probability & Statistics | C6: 884 | D6: 837 | E6: 0.94683258 | F6: 128.2729 | G6: 389106 | H6: 6112.2378 | I6: 6.5251507 | J6: 2.1510848 | K6: 8.2163034 | L6: 0.14510509 | M6: 440.16516
A7: Phi3:3.8b | B7: Adv Probability & Statistics | C7: 1000 | D7: 92 | E7: 0.092 | F7: 117.4365 | G7: 389492 | H7: 5804.9625 | I7: 0.78340209 | J7: 0.23620511 | K7: 0.95091053 | L7: 0.1174365 | M7: 389.492
A8: Qwen3:4b | B8: Adv Probability & Statistics | C8: 1000 | D8: 975 | E8: 0.975 | F8: 496.1365 | G8: 1507469 | H8: 21356.425 | I8: 1.965185 | J8: 0.64677947 | K8: 2.7392225 | L8: 0.4961365 | M8: 1507.469
A9: Gemma3:4b | B9: Calculus I | C9: 374 | D9: 323 | E9: 0.86363636 | F9: 72.6346 | G9: 187639 | H9: 4128.8227 | I9: 4.4469165 | J9: 1.7213905 | K9: 4.6938319 | L9: 0.19421016 | M9: 501.70856
A10: Phi3:3.8b | B10: Calculus I | C10: 900 | D10: 110 | E10: 0.12222222 | F10: 271.8522 | G10: 1070370 | H10: 11470.542 | I10: 0.40463163 | J10: 0.1027682 | K10: 0.57538692 | L10: 0.302058 | M10: 1189.3
A11: Qwen3:4b | B11: Calculus I | C11: 900 | D11: 718 | E11: 0.79777778 | F11: 441.2787 | G11: 1336068 | H11: 19454.995 | I11: 1.6270896 | J11: 0.5373978 | K11: 2.2143414 | L11: 0.49030967 | M11: 1484.52
A12: Gemma3:4b | B12: Grade 8 Math | C12: 644 | D12: 435 | E12: 0.67546584 | F12: 89.9217 | G12: 232337 | H12: 4697.0078 | I12: 4.837542 | J12: 1.8722804 | K12: 5.5567291 | L12: 0.13962997 | M12: 360.77174
A13: Phi3:3.8b | B13: Grade 8 Math | C13: 644 | D13: 16 | E13: 0.02484472 | F13: 79.643 | G13: 258025 | H13: 3842.0793 | I13: 0.2008965 | J13: 0.062009495 | K13: 0.2498647 | L13: 0.12366925 | M13: 400.65994
A14: Qwen3:4b | B14: Grade 8 Math | C14: 644 | D14: 504 | E14: 0.7826087 | F14: 355.8911 | G14: 977319 | H14: 13594.407 | I14: 1.4161635 | J14: 0.51569651 | K14: 2.2244442 | L14: 0.55262593 | M14: 1517.5761

Sheet Failure_Modes
A1: Failure Modes
A2: When a model is wrong, is it because the answer couldn't be parsed from the output, or because the parsed answer was the wrong number?
A3: How to read: High 'Extraction Failure Rate' = formatting problem (the model may know the answer but wrote it in a way we couldn't read). High 'Wrong Answer Rate' = real reasoning miss. 'Hard Failures' = calls that crashed or timed out.
A5: Model | B5: Dataset | C5: N | D5: Correct | E5: Incorrect (total) | F5: Extraction Failures | G5: Wrong Answers | H5: Hard Failures | I5: Extraction Failure Rate | J5: Wrong Answer Rate
A6: Gemma3:4b | B6: Adv Probability & Statistics | C6: 884 | D6: 837 | E6: 47 | F6: 0 | G6: 47 | H6: 0 | I6: 0 | J6: 0.053167421
A7: Phi3:3.8b | B7: Adv Probability & Statistics | C7: 1000 | D7: 92 | E7: 908 | F7: 0 | G7: 908 | H7: 0 | I7: 0 | J7: 0.908
A8: Qwen3:4b | B8: Adv Probability & Statistics | C8: 1000 | D8: 975 | E8: 25 | F8: 0 | G8: 25 | H8: 0 | I8: 0 | J8: 0.025
A9: Gemma3:4b | B9: Calculus I | C9: 374 | D9: 323 | E9: 51 | F9: 0 | G9: 51 | H9: 0 | I9: 0 | J9: 0.13636364
A10: Phi3:3.8b | B10: Calculus I | C10: 900 | D10: 110 | E10: 790 | F10: 0 | G10: 790 | H10: 0 | I10: 0 | J10: 0.87777778
A11: Qwen3:4b | B11: Calculus I | C11: 900 | D11: 718 | E11: 182 | F11: 0 | G11: 182 | H11: 0 | I11: 0 | J11: 0.20222222
A12: Gemma3:4b | B12: Grade 8 Math | C12: 644 | D12: 435 | E12: 209 | F12: 0 | G12: 209 | H12: 0 | I12: 0 | J12: 0.32453416
A13: Phi3:3.8b | B13: Grade 8 Math | C13: 644 | D13: 16 | E13: 628 | F13: 1 | G13: 627 | H13: 1 | I13: 0.001552795 | J13: 0.97360248
A14: Qwen3:4b | B14: Grade 8 Math | C14: 644 | D14: 504 | E14: 140 | F14: 0 | G14: 140 | H14: 0 | I14: 0 | J14: 0.2173913

Sheet Metric_Summary
A1: Metric Summary
A2: Typical per-question cost for each model: how long it takes, how many tokens it writes, how much energy it uses.
A3: How to read: 'Median' is the typical value; 'Mean' is the average (pulled by outliers). Use these to compare the everyday cost of each model.
A5: Model | B5: Dataset | C5: Metric | D5: N | E5: Mean | F5: Median | G5: Std Dev | H5: Q25 | I5: Q75 | J5: Min | K5: Max
A6: Gemma3:4b | B6: Adv Probability & Statistics | C6: processing_time_s | D6: 884 | E6: 6.9142961 | F6: 6.7875248 | G6: 2.5676831 | H6: 5.5251048 | I6: 7.8959873 | J6: 2.9843733 | K6: 66.245413
A7: Gemma3:4b | B7: Adv Probability & Statistics | C7: total_duration_s | D7: 884 | E7: 4.8716537 | F7: 4.74775 | G7: 2.5644396 | H7: 3.476925 | I7: 5.85915 | J7: 2.2757 | K7: 64.1924
A8: Gemma3:4b | B8: Adv Probability & Statistics | C8: eval_duration_s | D8: 884 | E8: 4.2093469 | F8: 4.0847 | G8: 2.4315982 | H8: 2.8807 | I8: 5.1671 | J8: 1.7453 | K8: 60.5102
A9: Gemma3:4b | B9: Adv Probability & Statistics | C9: eval_count | D9: 884 | E9: 440.16516 | F9: 431 | G9: 247.54309 | H9: 295.75 | I9: 552.5 | J9: 183 | K9: 5851
A10: Gemma3:4b | B10: Adv Probability & Statistics | C10: prompt_eval_count | D10: 884 | E10: 315.0181 | F10: 313 | G10: 24.086098 | H10: 295 | I10: 319 | J10: 290 | K10: 385
A11: Gemma3:4b | B11: Adv Probability & Statistics | C11: generation_speed_tps | D11: 884 | E11: 103.93356 | F11: 105.125 | G11: 4.9426048 | H11: 101.81 | I11: 107.14 | J11: 59.13 | K11: 114.23
A12: Gemma3:4b | B12: Adv Probability & Statistics | C12: prompt_processing_speed_tps | D12: 884 | E12: 3467.9916 | F12: 3532.875 | G12: 1439.5448 | H12: 2354.2075 | I12: 4523.05 | J12: 862.48 | K12: 17803.78
A13: Gemma3:4b | B13: Adv Probability & Statistics | C13: energy_estimate_wh | D13: 884 | E13: 0.14510509 | F13: 0.14205 | G13: 0.076172753 | H13: 0.1032 | I13: 0.1763 | J13: 0.0594 | K13: 1.8815
A14: Gemma3:4b | B14: Adv Probability & Statistics | C14: gpu_power_avg_w | D14: 884 | E14: 73.49491 | F14: 75.4 | G14: 9.1004839 | H14: 67.2 | I14: 80.1 | J14: 46.8 | K14: 102.2
A15: Gemma3:4b | B15: Adv Probability & Statistics | C15: gpu_vram_peak_mb | D15: 884 | E15: 4317.5465 | F15: 4322.9 | G15: 7.5796726 | H15: 4314.4 | I15: 4322.9 | J15: 4296.2 | K15: 4323.4
A16: Gemma3:4b | B16: Adv Probability & Statistics | C16: ram_peak_mb | D16: 884 | E16: 34595.111 | F16: 34754.9 | G16: 720.83219 | H16: 34228.8 | I16: 35052.375 | J16: 31987.3 | K16: 35769.2
A17: Gemma3:4b | B17: Calculus I | C17: processing_time_s | D17: 374 | E17: 11.039633 | F17: 9.26309 | G17: 11.509688 | H17: 7.8498744 | I17: 11.408987 | J17: 5.2864156 | K17: 205.98276
... A104: Qwen3:4b | B104: Grade 8 Math | C104: ram_peak_mb | D104: 644 | E104: 26785.883 | F104: 26779.15 | G104: 106.98691 | H104: 26727.625 | I104: 26845.2 | J104: 26505.7 | K104: 27226.4

Sheet McNemar
A1: McNemar
A2: For each pair of models on each dataset: are the accuracy scores actually different, or is the gap within the noise?
A3: How to read: Look at 'Significant @ α=0.05 (Holm)?' — TRUE (green) means the two models really do differ. 'A Correct, B Wrong' and 'B Correct, A Wrong' show who won on the disagreed questions. 'Cohen's h' is the size of the gap (0.2 small, 0.5 medium, 0.8 large).
A5: Dataset | B5: Model A | C5: Model B | D5: N | E5: Accuracy A | F5: Accuracy B | G5: Accuracy Diff (A − B) | H5: A Correct, B Wrong | I5: B Correct, A Wrong | J5: Both Correct | K5: Both Wrong | L5: Discordant Pairs | M5: Test Statistic | N5: Method | O5: p-value (raw) | P5: Cohen's h | Q5: Cohen's h Magnitude | R5: p-value (Holm-adjusted) | S5: Significant @ α=0.05 (Holm)?
A6: Adv Probability & Statistics | B6: Gemma3:4b | C6: Phi3:3.8b | D6: 884 | E6: 0.94683258 | F6: 0.1040724 | G6: 0.84276018 | H6: 747 | I6: 2 | J6: 90 | K6: 45 | L6: 749 | M6: 739.03338 | N6: chi2_corrected | O6: 9.7266522e-163 | P6: 2.0192885 | Q6: large | R6: 1.9453304e-162 | S6: =TRUE()
A7: Adv Probability & Statistics | B7: Gemma3:4b | C7: Qwen3:4b | D7: 884 | E7: 0.94683258 | F7: 0.9739819 | G7: -0.027149321 | H7: 16 | I7: 40 | J7: 821 | K7: 7 | L7: 56 | M7: 9.4464286 | N7: chi2_corrected | O7: 0.0021156065 | P7: -0.14133058 | Q7: negligible | R7: 0.0021156065 | S7: =TRUE()
A8: Adv Probability & Statistics | B8: Phi3:3.8b | C8: Qwen3:4b | D8: 1000 | E8: 0.092 | F8: 0.975 | G8: -0.883 | H8: 0 | I8: 883 | J8: 92 | K8: 25 | L8: 883 | M8: 881.00113 | N8: chi2_corrected | O8: 1.3243265e-193 | P8: -2.2076929 | Q8: large | R8: 3.9729795e-193 | S8: =TRUE()
A9: Calculus I | B9: Gemma3:4b | C9: Phi3:3.8b | D9: 374 | E9: 0.86363636 | F9: 0.28877005 | G9: 0.57486631 | H9: 222 | I9: 7 | J9: 101 | K9: 44 | L9: 229 | M9: 199.98253 | N9: chi2_corrected | O9: 2.1068986e-45 | P9: 1.2504975 | Q9: large | R9: 4.2137973e-45 | S9: =TRUE()
A10: Calculus I | B10: Gemma3:4b | C10: Qwen3:4b | D10: 374 | E10: 0.86363636 | F10: 0.79411765 | G10: 0.069518717 | H10: 37 | I10: 11 | J10: 286 | K10: 40 | L10: 48 | M10: 13.020833 | N10: chi2_corrected | O10: 0.00030804471 | P10: 0.18546502 | Q10: negligible | R10: 0.00030804471 | S10: =TRUE()
A11: Calculus I | B11: Phi3:3.8b | C11: Qwen3:4b | D11: 900 | E11: 0.12222222 | F11: 0.79777778 | G11: -0.67555556 | H11: 17 | I11: 625 | J11: 93 | K11: 165 | L11: 642 | M11: 573.9081 | N11: chi2_corrected | O11: 7.9287553e-127 | P11: -1.4944588 | Q11: large | R11: 2.3786266e-126 | S11: =TRUE()
A12: Grade 8 Math | B12: Gemma3:4b | C12: Phi3:3.8b | D12: 644 | E12: 0.67546584 | F12: 0.02484472 | G12: 0.65062112 | H12: 422 | I12: 3 | J12: 13 | K12: 206 | L12: 425 | M12: 411.11529 | N12: chi2_corrected | O12: 2.0958316e-91 | P12: 1.6127979 | Q12: large | R12: 4.1916632e-91 | S12: =TRUE()
A13: Grade 8 Math | B13: Gemma3:4b | C13: Qwen3:4b | D13: 644 | E13: 0.67546584 | F13: 0.7826087 | G13: -0.10714286 | H13: 8 | I13: 77 | J13: 427 | K13: 132 | L13: 85 | M13: 54.4 | N13: chi2_corrected | O13: 1.6356287e-13 | P13: -0.24213088 | Q13: small | R13: 1.6356287e-13 | S13: =TRUE()
A14: Grade 8 Math | B14: Phi3:3.8b | C14: Qwen3:4b | D14: 644 | E14: 0.02484472 | F14: 0.7826087 | G14: -0.75776398 | H14: 3 | I14: 491 | J14: 13 | K14: 137 | L14: 494 | M14: 480.09919 | N14: chi2_corrected | O14: 2.0331063e-106 | P14: -1.8549287 | Q14: large | R14: 6.099319e-106 | S14: =TRUE()

Sheet Metric_Comparison
A1: Metric Comparison
A2: For each pair of models, does one use significantly more/less time, tokens, or energy per question?
A3: How to read: 'Significant (Holm)?' TRUE (green) = the difference is real. 'Median A' vs 'Median B' shows which is larger. 'Cliff's δ' is the size of the gap (values near 0 = tiny, near ±1 = huge). p-values are corrected for running multiple tests.
A5: Dataset | B5: Metric | C5: Model A | D5: Model B | E5: N Pairs | F5: Median A | G5: Median B | H5: Wilcoxon Median Diff | I5: Wilcoxon W | J5: Wilcoxon p (raw) | K5: Wilcoxon p (Holm) | L5: Wilcoxon Significant (Holm)? | M5: Cliff's δ | N5: Cliff's δ Magnitude
A6: Adv Probability & Statistics | B6: Generation Time (s) | C6: Gemma3:4b | D6: Phi3:3.8b | E6: 884 | F6: 6.7875248 | G6: 4.3550689 | H6: 2.1010976 | I6: 53592 | J6: 5.0748605e-78 | K6: 5.0748605e-78 | L6: =TRUE() | M6: 0.65585266 | N6: large
A7: Adv Probability & Statistics | B7: Generation Time (s) | C7: Gemma3:4b | D7: Qwen3:4b | E7: 884 | F7: 6.7875248 | G7: 18.248519 | H7: -12.182547 | I7: 865 | J7: 5.1720732e-145 | K7: 1.0344146e-144 | L7: =TRUE() | M7: -0.99522686 | N7: large
A8: Adv Probability & Statistics | B8: Generation Time (s) | C8: Phi3:3.8b | D8: Qwen3:4b | E8: 1000 | F8: 4.3344312 | G8: 18.360233 | H8: -13.713174 | I8: 8925 | J8: 8.970215e-154 | K8: 2.6910645e-153 | L8: =TRUE() | M8: -0.953178 | N8: large
A9: Adv Probability & Statistics | B9: Generation Speed (tps) | C9: Gemma3:4b | D9: Phi3:3.8b | E9: 884 | F9: 105.125 | G9: 137.51 | H9: -33.325 | I9: 5087 | J9: 7.04032e-139 | K9: 7.04032e-139 | L9: =TRUE() | M9: -0.89413479 | N9: large
A10: Adv Probability & Statistics | B10: Generation Speed (tps) | C10: Gemma3:4b | D10: Qwen3:4b | E10: 884 | F10: 105.125 | G10: 82.355 | H10: 21.815 | I10: 1180 | J10: 2.1925854e-144 | K10: 4.3851708e-144 | L10: =TRUE() | M10: 0.93822813 | N10: large
A11: Adv Probability & Statistics | B11: Generation Speed (tps) | C11: Phi3:3.8b | D11: Qwen3:4b | E11: 1000 | F11: 137.505 | G11: 82.2 | H11: 54.06 | I11: 84 | J11: 4.2796636e-165 | K11: 1.2838991e-164 | L11: =TRUE() | M11: 0.988579 | N11: large
A12: Adv Probability & Statistics | B12: Output Tokens | C12: Gemma3:4b | D12: Phi3:3.8b | E12: 884 | F12: 431 | G12: 239.5 | H12: 146 | I12: 91721.5 | J12: 2.2392184e-42 | K12: 2.2392184e-42 | L12: =TRUE() | M12: 0.46920108 | N12: medium
A13: Adv Probability & Statistics | B13: Output Tokens | C13: Gemma3:4b | D13: Qwen3:4b | E13: 884 | F13: 431 | G13: 1260.5 | H13: -896.5 | I13: 880 | J13: 5.4402102e-145 | K13: 1.6320631e-144 | L13: =TRUE() | M13: -0.98664032 | N13: large
A14: Adv Probability & Statistics | B14: Output Tokens | C14: Phi3:3.8b | D14: Qwen3:4b | E14: 1000 | F14: 237 | G14: 1262.5 | H14: -992 | I14: 16571 | J14: 2.60818e-144 | K14: 5.21636e-144 | L14: =TRUE() | M14: -0.924251 | N14: large
A15: Adv Probability & Statistics | B15: Energy per Question (Wh) | C15: Gemma3:4b | D15: Phi3:3.8b | E15: 884 | F15: 0.14205 | G15: 0.07545 | H15: 0.0534 | I15: 63426 | J15: 7.7387423e-68 | K15: 7.7387423e-68 | L15: =TRUE() | M15: 0.58794865 | N15: large
A16: Adv Probability & Statistics | B16: Energy per Question (Wh) | C16: Gemma3:4b | D16: Qwen3:4b | E16: 884 | F16: 0.14205 | G16: 0.4233 | H16: -0.3019 | I16: 876 | J16: 5.3679495e-145 | K16: 1.0735899e-144 | L16: =TRUE() | M16: -0.99107435 | N16: large
A17: Adv Probability & Statistics | B17: Energy per Question (Wh) | C17: Phi3:3.8b | D17: Qwen3:4b | E17: 1000 | F17: 0.0749 | G17: 0.4221 | H17: -0.3379 | I17: 11841.5 | J17: 3.9667722e-150 | K17: 1.1900317e-149 | L17: =TRUE() | M17: -0.942971 | N17: large
... A41: Grade 8 Math | B41: Energy per Question (Wh) | C41: Phi3:3.8b | D41: Qwen3:4b | E41: 643 | F41: 0.0729 | G41: 0.416 | H41: -0.3263 | I41: 3579 | J41: 7.8506001e-100 | K41: 1.57012e-99 | L41: =TRUE() | M41: -0.93257209 | N41: large

Sheet Run_Variance
A1: Run Variance
A2: How much the accuracy wobbles if you re-run the same model on the same dataset.
A3: How to read: Small 'Accuracy SD' across runs = results are stable and trustworthy. Large SD = re-running could flip the story; treat the headline numbers with caution.
A5: Model | B5: Dataset | C5: Runs | D5: Accuracy (mean) | E5: Accuracy SD | F5: Accuracy Min | G5: Accuracy Max | H5: Mean Time SD (s) | I5: Mean Energy SD (Wh)
A6: Gemma3:4b | B6: Adv Probability & Statistics | C6: 2 | D6: 0.94291629 | E6: 0.0055384699 | F6: 0.939 | G6: 0.94683258 | H6: 0.66852325 | I6: 0.01403742
A7: Phi3:3.8b | B7: Adv Probability & Statistics | C7: 2 | D7: 0.0765 | E7: 0.02192031 | F7: 0.061 | G7: 0.092 | H7: 1.3312822 | I7: 0.038786787
A8: Qwen3:4b | B8: Adv Probability & Statistics | C8: 3 | D8: 0.97366667 | E8: 0.0011547005 | F8: 0.973 | G8: 0.975 | H8: 3.3685254 | I8: 0.057639877
A9: Gemma3:4b | B9: Calculus I | C9: 3 | D9: 0.8589899 | E9: 0.0041745411 | F9: 0.85555556 | G9: 0.86363636 | H9: 1.5358037 | I9: 0.0059498214
A10: Phi3:3.8b | B10: Calculus I | C10: 2 | D10: 0.12111111 | E10: 0.0015713484 | F10: 0.12 | G10: 0.12222222 | H10: 6.1173182 | I10: 0.1657232
A11: Qwen3:4b | B11: Calculus I | C11: 4 | D11: 0.79574173 | E11: 0.014935729 | F11: 0.77419355 | G11: 0.80777778 | H11: 845.19162 | I11: 7.6206079
A12: Gemma3:4b | B12: Grade 8 Math | C12: 2 | D12: 0.66847826 | E12: 0.0098819271 | F12: 0.66149068 | G12: 0.67546584 | H12: 0.86945502 | I12: 0.012469894
A13: Phi3:3.8b | B13: Grade 8 Math | C13: 2 | D13: 0.026397516 | E13: 0.0021959838 | F13: 0.02484472 | G13: 0.027950311 | H13: 1.4286216 | I13: 0.041277578
A14: Qwen3:4b | B14: Grade 8 Math | C14: 3 | D14: 0.76140711 | E14: 0.034068107 | F14: 0.72210953 | G14: 0.7826087 | H14: 0.53328222 | I14: 0.026095148

Sheet Glossary
A1: Glossary
A2: Plain-English definitions for every statistical term used in this workbook.
A3: How to read: use Ctrl+F to search. Terms are listed in roughly the order they appear in other sheets.
A5: Term | B5: Explanation
A6: Accuracy | B6: Fraction of questions the model got right. 94.7% means 94.7 out of every 100 answers were correct.
A7: N | B7: Number of questions. Larger N makes the result more trustworthy.
A8: 95% Confidence Interval (CI) | B8: The range the true accuracy is very likely to fall in. If the CI is 62% – 70%, the true score is almost certainly somewhere in that window. Narrower = more certain.
A9: Wilson CI | B9: The specific formula used for the accuracy CI. It is well-behaved for small samples and for scores close to 0% or 100%.
A10: p-value | B10: How surprising the observed difference would be if the two models were actually equal. Small p = unlikely to be a fluke. We treat p < 0.05 as 'statistically significant' (green-shaded cells).
A11: Holm-adjusted p-value | B11: Same idea as a p-value, but inflated to account for running several tests at once (3 pairs of models × multiple metrics). Always use this one — not the raw p — to call something significant.
A12: Significant (Holm)? | B12: TRUE (green) means the gap between the two models is real at the 95% confidence level after accounting for multiple tests. FALSE (gray) means the gap is within noise.
A13: McNemar's test | B13: The formal test for 'do two models get different numbers of questions right on the same quiz?' It focuses on questions where the models disagreed.
A14: Cohen's h | B14: How big an accuracy gap is, on a standardized scale. Rule of thumb: 0.2 = small, 0.5 = medium, 0.8 = large.
A15: Wilcoxon signed-rank test | B15: The formal test for 'does one model typically use more time / tokens / energy than the other on the same questions?' Makes no assumption that the data is bell-shaped.
A16: Cliff's δ (delta) | B16: How big the time/energy/token gap is, on a −1 to +1 scale. |δ| < 0.15 ≈ negligible, < 0.33 ≈ small, < 0.47 ≈ medium, bigger ≈ large.
... A22: Latest run | B22: When the same (model, dataset) has been benchmarked more than once, the headline sheets use only the most recent run so that each pair of models is compared on identical data.
